<?xml version='1.0'?>
<sdf version="1.4">
  <model name="single_pendulum">
    <link name="base">
      <inertial>
        <mass>1000</mass>
      </inertial>
      <visual name="vis_plate_on_ground">
        <pose>0 0 0.01  0 0 0</pose>
        <geometry>
          <cylinder>
            <radius>0.8</radius>
            <length>0.02</length>
          </cylinder>
        </geometry>
        <!--<material>
          <script>
            <uri>file://media/materials/scripts/gazebo.material</uri>
            <name>Gazebo/Grey</name>
          </script>
        </material>-->
      </visual>
      <visual name="vis_pole">
        <pose>-0.275 0 1.1  0 0 0</pose>
        <geometry>
          <box><size>0.2 0.2 2.2</size></box>
        </geometry>
        <!--<material>
          <script>
            <uri>file://media/materials/scripts/gazebo.material</uri>
            <name>Gazebo/Grey</name>
          </script>
        </material>-->
      </visual>
      <collision name="col_plate_on_ground">
        <pose>0 0 0.01  0 0 0</pose>
        <geometry>
          <cylinder>
            <radius>0.8</radius>
            <length>0.02</length>
          </cylinder>
        </geometry>
      </collision>
      <collision name="col_pole">
        <pose>-0.275 0 1.1  0 0 0</pose>
        <geometry>
          <box><size>0.2 0.2 2.2</size></box>
        </geometry>
      </collision>
    </link>
    <!-- upper link, length 1, IC -90 degrees -->
    <link name="upper_link">
      <pose>0 0 2.1  -1.5708 0 0</pose>
      <self_collide>0</self_collide>
      <inertial>
        <pose>0 0 0.5  0 0 0</pose>
      </inertial>
      <visual name="vis_upper_joint">
        <pose>-0.05 0 0  0 1.5708 0</pose>
        <geometry>
          <cylinder>
            <radius>0.1</radius>
            <length>0.3</length>
          </cylinder>
        </geometry>
       <!-- <material>
          <script>
            <uri>file://media/materials/scripts/gazebo.material</uri>
            <name>Gazebo/Grey</name>
          </script>
        </material>-->
      </visual>
      <visual name="vis_lower_joint">
        <pose>0 0 1.0  0 1.5708 0</pose>
        <geometry>
          <cylinder>
            <radius>0.1</radius>
            <length>0.2</length>
          </cylinder>
        </geometry>
       <!-- <material>
          <script>
            <uri>file://media/materials/scripts/gazebo.material</uri>
            <name>Gazebo/Grey</name>
          </script>
        </material>-->
      </visual>
      <visual name="vis_cylinder">
        <pose>0 0 0.5  0 0 0</pose>
        <geometry>
          <cylinder>
            <radius>0.1</radius>
            <length>0.9</length>
          </cylinder>
        </geometry>
        <!--<material>
          <script>
            <uri>file://media/materials/scripts/gazebo.material</uri>
            <name>Gazebo/Grey</name>
          </script>
        </material>-->
      </visual>
    </link>
   
    <joint name="upper_joint" type="revolute">
      <parent>base</parent>
      <child>upper_link</child>
      <axis>
        <xyz>1.0 0 0</xyz>
      </axis>
    </joint>
    
    <plugin name="controlboard" filename="libgazebo_yarp_controlboard.so">
        <yarpConfigurationFile>model://single_pendulum/conf/gazebo_controlboard.ini</yarpConfigurationFile>
        <initialConfiguration>0.0 0.0</initialConfiguration>
    </plugin>
    
  </model>
</sdf>
